Workbook

Sheet PROGRESSION
A1: GELARAN MAJU SDN BHD
A2: PROJECT: THE CAPITOL / MSK
A3: Report Date: 12 SEPTEMBER 2026
A4: LEVEL | C4: COLD WATER | G4: =(C46+D46+E46+F46+G46+H46+I46)/7 -> 0.47607143 | J4: SANITARY | L4: =(J46+K46+L46+M46+N46)/5 -> 0.47025 | O4: IRRIGATION | Q4: =(O46+P46+Q46+R46)/4 -> 0.06125 | T4: SUPAHAM | U4: LEADER | V4: ASSISTANT
C5: PIPE SLEEVE | D5: PUMP | E5: PUMP CONTROL PANEL | F5: TRANSFER PUMP PIPES | G5: L31 & 31M ROOF PIPING | H5: CW TENANT | I5: BACKSHAFT CW & FW TOILETS | J5: HOSEREEL FLOORTRAP & STACK | K5: SANITARY TENANT | L5: TOILET PIPE DISTRIBUTION & HACKING | M5: SANITARY TOILETS | N5: SANITARY WARES INSTALLATION | O5: IRRIGATION OUTLET | P5: IRRIGATION INLET | Q5: IRRIGATION WIRING | R5: IRRIGATION CONTROL PANEL | T5: team 1 | U5: SOLIHIN | V5: ASHRAFUL | W5: JIARUL | X5: YASIN
A6: 13 | B6: TOWER A | C6: 1 | D6: N/A | E6: N/A | F6: 0.95 | G6: N/A | H6: 0.95 | I6: 0 | J6: 0.95 | K6: 0.95 | L6: =0/4 -> 0 | M6: =0/4 -> 0 | N6: 0 | O6: 1 | P6: 0.9 | Q6: 0 | R6: N/A | T6: team 2 | U6: ASGAR | V6: RANA
A7: 14 | C7: 1 | F7: 0.95 | H7: 0.95 | I7: 0.95 | J7: 0.95 | K7: 0.95 | L7: 0.95 | M7: 0.95 | N7: 0.95 | O7: 1 | P7: 0 | Q7: 0 | T7: team 3 | U7: SUHAIRI | V7: SUPENDI
A8: 15 | C8: 1 | F8: 0.95 | H8: 0.95 | I8: 0.95 | J8: 0.95 | K8: 0.95 | L8: 0.95 | M8: 0.95 | N8: 0.95 | O8: 0.95 | P8: 0 | Q8: 0 | T8: team 4 | U8: BILAL | V8: FARHAD | W8: SOFIKUL | X8: SYAHIB | Y8: AMIRUL | Z8: NURUL | AA8: NAZMUL
A9: 16 | C9: 1 | F9: 0.95 | H9: 0.95 | I9: 0.95 | J9: 0.5 | K9: 0.5 | L9: =4/4 -> 1 | M9: 0.95 | N9: 0.95 | O9: 0.95 | P9: 0 | Q9: 0 | T9: team 5 | U9: JUWEL | V9: BADOL
A10: 17 | C10: 1 | F10: 0.95 | H10: 0.95 | I10: 0 | J10: 0.5 | K10: 0.5 | L10: =4/4 -> 1 | M10: 0.95 | N10: 0.1 | O10: 0 | P10: 0 | Q10: 0 | T10: team 6 | U10: JILLUR | V10: ISLAM
A11: 18 | C11: 1 | F11: 0.95 | H11: 0.95 | I11: 0 | J11: 0.5 | K11: 0.5 | L11: =4/4 -> 1 | M11: 0.95 | N11: 0 | O11: 0.1 | P11: 0 | Q11: 0 | T11: team 7 | U11: SARIP | V11: SYAHIB
A12: 19 | C12: 1 | F12: 0.95 | H12: 0.95 | I12: 0 | J12: 0.5 | K12: 0.5 | L12: =4/4 -> 1 | M12: 0.95 | N12: 0 | O12: 0 | P12: 0 | Q12: 0 | T12: team 8 | U12: EMON | V12: MAHMUD
A13: 20 | C13: 1 | F13: 0.95 | H13: 0.95 | I13: 0 | J13: 0.95 | K13: 0.95 | L13: 0.2 | M13: 0.95 | N13: 0 | O13: 0 | P13: 0 | Q13: 0 | T13: team 9 | U13: IBNU | V13: DAMIL
A14: 21 | C14: 1 | F14: 0.95 | H14: 0.95 | I14: 0 | J14: 0.95 | K14: 0.95 | L14: 0 | M14: 0.95 | N14: 0 | O14: 0 | P14: 0 | Q14: 0 | T14: team 10 | U14: KAMAL
A15: 22 | C15: 1 | F15: 0.95 | H15: 0.95 | I15: 0 | J15: 0.95 | K15: 0.95 | L15: 0.95 | M15: 0.95 | N15: 0 | O15: 0 | P15: 0 | Q15: 0 | R15: 0
A16: 23 | C16: 1 | F16: 0.95 | H16: 0.95 | I16: 0 | J16: 0.5 | K16: 0.5 | L16: =0/4 -> 0 | M16: 0.95 | N16: 0 | O16: 0 | P16: 0 | Q16: 0 | R16: N/A
A17: 24 | C17: 1 | F17: 0.95 | H17: 0.95 | I17: 0 | J17: 0.5 | K17: 0.5 | L17: =0/4 -> 0 | M17: 0.95 | N17: 0 | O17: 0 | P17: 0 | Q17: 0
A18: 25 | C18: 1 | F18: 0.95 | H18: 0.95 | I18: 0 | J18: 0.95 | K18: 0.95 | L18: =0/4 -> 0 | M18: 0.95 | N18: 0 | O18: 0 | P18: 0 | Q18: 0
A19: 26 | C19: 1 | F19: 0.95 | H19: 0.95 | I19: 0 | J19: 0.95 | K19: 0.95 | L19: 0.95 | M19: 0.95 | N19: 0 | O19: 0 | P19: 0 | Q19: 0
A20: 27 | C20: 1 | F20: 0.95 | H20: 0.95 | I20: 0 | J20: 0.95 | K20: 0.95 | L20: =0/4 -> 0 | M20: 0.95 | N20: 0 | O20: 0 | P20: 0 | Q20: 0
A21: 28 | C21: 1 | F21: 0.95 | H21: 0.95 | I21: 0 | J21: =0/6 -> 0 | K21: 0 | L21: =0/4 -> 0 | M21: =0/4 -> 0 | N21: 0 | O21: 0 | P21: 0 | Q21: 0
A22: 29 | C22: 1 | F22: 0 | H22: 0.95 | I22: 0 | J22: =0/6 -> 0 | K22: 0 | L22: =0/4 -> 0 | M22: =0/4 -> 0 | N22: 0 | O22: 0 | P22: 0 | Q22: 0
A23: 30 | C23: 1 | F23: 0 | H23: 0 | I23: 0 | J23: =0/6 -> 0 | K23: 0 | L23: =0/4 -> 0 | M23: =0/4 -> 0 | N23: 0 | O23: 0 | P23: 0 | Q23: 0
A24: 31 | C24: 0.55 | D24: 0.95 | E24: 0.95 | F24: 0 | G24: 0 | H24: 0 | I24: 0 | J24: =0/6 -> 0 | K24: 0 | L24: =0/4 -> 0 | M24: =0/4 -> 0 | N24: 0 | O24: 0 | P24: 0 | Q24: 0
A25: 31M | C25: 0.1 | D25: 0 | E25: 0 | F25: 0 | G25: 0 | H25: 0 | I25: 0 | J25: =0/6 -> 0 | K25: 0 | L25: =0/4 -> 0 | M25: =0/4 -> 0 | N25: 0 | O25: 0 | P25: 0 | Q25: 0 | R25: 0
A26: 13 | B26: TOWER B | C26: 1 | D26: N/A | E26: N/A | F26: 0.95 | G26: N/A | H26: 0.95 | I26: 0 | J26: 0.95 | K26: 0.95 | L26: =0/4 -> 0 | M26: =0/4 -> 0 | N26: 0 | O26: 1 | P26: 0.9 | Q26: 0 | R26: N/A
A27: 14 | C27: 1 | F27: 0.95 | H27: 0.95 | I27: 0.95 | J27: 0.95 | K27: 0.95 | L27: 0.95 | M27: 0.95 | N27: 0.95 | O27: 1 | P27: 0 | Q27: 0
A28: 15 | C28: 1 | F28: 0.95 | H28: 0.95 | I28: 0.95 | J28: 0.95 | K28: 0.95 | L28: 0.95 | M28: 0.95 | N28: 0.95 | O28: 0.95 | P28: 0 | Q28: 0
A29: 16 | C29: 1 | F29: 0.95 | H29: 0.95 | I29: 0.1 | J29: 0.5 | K29: 0.5 | L29: 0.95 | M29: 0.95 | N29: 0.95 | O29: 0.95 | P29: 0 | Q29: 0
A30: 17 | C30: 1 | F30: 0.95 | H30: 0.95 | I30: 0 | J30: 0.5 | K30: 0.5 | L30: 0.95 | M30: 0.95 | N30: 0.1 | O30: 0 | P30: 0 | Q30: 0
A31: 18 | C31: 1 | F31: 0.95 | H31: 0.95 | I31: 0 | J31: 0.5 | K31: 0.5 | L31: 0.95 | M31: 0.95 | N31: 0 | O31: 0.1 | P31: 0 | Q31: 0
A32: 19 | C32: 1 | F32: 0.95 | H32: 0.95 | I32: 0 | J32: 0.5 | K32: 0.5 | L32: 0.95 | M32: 0.95 | N32: 0 | O32: 0 | P32: 0 | Q32: 0
A33: 20 | C33: 1 | F33: 0 | H33: 0.95 | I33: 0 | J33: 0.95 | K33: 0.95 | L33: 0.2 | M33: 0.95 | N33: 0 | O33: 0 | P33: 0 | Q33: 0
A34: 21 | C34: 1 | F34: 0 | H34: 0.95 | I34: 0 | J34: 0.95 | K34: 0.95 | L34: =0/4 -> 0 | M34: 0.95 | N34: 0 | O34: 0 | P34: 0 | Q34: 0
A35: 22 | C35: 1 | F35: 0 | H35: 0.95 | I35: 0 | J35: 0.95 | K35: 0.95 | L35: 0.95 | M35: 0.95 | N35: 0 | O35: 0 | P35: 0 | Q35: 0 | R35: 0
A36: 23 | C36: 1 | F36: 0 | H36: 0.95 | I36: 0 | J36: 0.5 | K36: 0.5 | L36: =0/4 -> 0 | M36: 0.95 | N36: 0 | O36: 0 | P36: 0 | Q36: 0 | R36: N/A
A37: 24 | C37: 1 | F37: 0 | H37: 0.95 | I37: 0 | J37: 0.5 | K37: 0.5 | L37: =0/4 -> 0 | M37: 0.5 | N37: 0 | O37: 0 | P37: 0 | Q37: 0
A38: 25 | C38: 1 | F38: 0 | H38: 0.95 | I38: 0 | J38: 0.95 | K38: 0.95 | L38: =0/4 -> 0 | M38: 0.95 | N38: 0 | O38: 0 | P38: 0 | Q38: 0
A39: 26 | C39: 1 | F39: 0 | H39: 0.95 | I39: 0 | J39: 0.95 | K39: 0.95 | L39: 0.95 | M39: 0.95 | N39: 0 | O39: 0 | P39: 0 | Q39: 0
A40: 27 | C40: 1 | F40: 0 | H40: 0.95 | I40: 0 | J40: 0.95 | K40: 0.95 | L40: =0/4 -> 0 | M40: 0.95 | N40: 0 | O40: 0 | P40: 0 | Q40: 0
...

Sheet COMPARE
A1: Tower A vs Tower B | % complete
A2: =IF(C8=D8,"Overall tied",IF(C8>D8,"Tower A leads overall by "&TEXT(C8-D8,"0.0%"),"Tower B leads overall by "&TEXT(D8-C8,"0.0%"))) -> Tower A leads overall by 3.5%
A4: PACKAGE | C4: Tower A | D4: Tower B | E4: Gap (A−B) | F4: Leader
A5: COLD WATER | C5: =AVERAGE(C11:C17) -> 0.51321429 | D5: =AVERAGE(D11:D17) -> 0.43892857 | E5: =C5-D5 -> 0.074285714 | F5: =IF(C5=D5,"Tie",IF(C5>D5,"Tower A","Tower B")) -> Tower A
A6: SANITARY | C6: =AVERAGE(C18:C22) -> 0.4735 | D6: =AVERAGE(D18:D22) -> 0.467 | E6: =C6-D6 -> 0.0065 | F6: =IF(C6=D6,"Tie",IF(C6>D6,"Tower A","Tower B")) -> Tower A
A7: IRRIGATION | C7: =AVERAGE(C23:C26) -> 0.06125 | D7: =AVERAGE(D23:D26) -> 0.06125 | E7: =C7-D7 -> 0 | F7: =IF(C7=D7,"Tie",IF(C7>D7,"Tower A","Tower B")) -> Tie
A8: OVERALL | C8: =AVERAGE(C11:C26) -> 0.3878125 | D8: =AVERAGE(D11:D26) -> 0.35328125 | E8: =C8-D8 -> 0.03453125 | F8: =IF(C8=D8,"Tie",IF(C8>D8,"Tower A","Tower B")) -> Tower A
A10: PACKAGE | B10: Item | C10: Tower A | D10: Tower B | E10: Gap (A−B) | F10: Leader
A11: Cold Water | B11: Pipe Sleeve | C11: =AVERAGE(PROGRESSION!C6:C25) -> 0.9325 | D11: =AVERAGE(PROGRESSION!C26:C45) -> 0.93 | E11: =C11-D11 -> 0.0025 | F11: =IF(C11=D11,"Tie",IF(C11>D11,"Tower A","Tower B")) -> Tower A
A12: Cold Water | B12: Pump | C12: =AVERAGE(PROGRESSION!D6:D25) -> 0.475 | D12: =AVERAGE(PROGRESSION!D26:D45) -> 0.475 | E12: =C12-D12 -> 0 | F12: =IF(C12=D12,"Tie",IF(C12>D12,"Tower A","Tower B")) -> Tie
A13: Cold Water | B13: Pump Control Panel | C13: =AVERAGE(PROGRESSION!E6:E25) -> 0.475 | D13: =AVERAGE(PROGRESSION!E26:E45) -> 0.475 | E13: =C13-D13 -> 0 | F13: =IF(C13=D13,"Tie",IF(C13>D13,"Tower A","Tower B")) -> Tie
A14: Cold Water | B14: Transfer Pump Pipes | C14: =AVERAGE(PROGRESSION!F6:F25) -> 0.76 | D14: =AVERAGE(PROGRESSION!F26:F45) -> 0.3325 | E14: =C14-D14 -> 0.4275 | F14: =IF(C14=D14,"Tie",IF(C14>D14,"Tower A","Tower B")) -> Tower A
A15: Cold Water | B15: L31 & 31M Roof Piping | C15: =AVERAGE(PROGRESSION!G6:G25) -> 0 | D15: =AVERAGE(PROGRESSION!G26:G45) -> 0 | E15: =C15-D15 -> 0 | F15: =IF(C15=D15,"Tie",IF(C15>D15,"Tower A","Tower B")) -> Tie
A16: Cold Water | B16: CW Tenant | C16: =AVERAGE(PROGRESSION!H6:H25) -> 0.8075 | D16: =AVERAGE(PROGRESSION!H26:H45) -> 0.76 | E16: =C16-D16 -> 0.0475 | F16: =IF(C16=D16,"Tie",IF(C16>D16,"Tower A","Tower B")) -> Tower A
A17: Cold Water | B17: Backshaft CW & FW Toilets | C17: =AVERAGE(PROGRESSION!I6:I25) -> 0.1425 | D17: =AVERAGE(PROGRESSION!I26:I45) -> 0.1 | E17: =C17-D17 -> 0.0425 | F17: =IF(C17=D17,"Tie",IF(C17>D17,"Tower A","Tower B")) -> Tower A
A18: Sanitary | B18: Hosereel Floortrap & Stack | C18: =AVERAGE(PROGRESSION!J6:J25) -> 0.5775 | D18: =AVERAGE(PROGRESSION!J26:J45) -> 0.5775 | E18: =C18-D18 -> 0 | F18: =IF(C18=D18,"Tie",IF(C18>D18,"Tower A","Tower B")) -> Tie
A19: Sanitary | B19: Sanitary Tenant | C19: =AVERAGE(PROGRESSION!K6:K25) -> 0.5775 | D19: =AVERAGE(PROGRESSION!K26:K45) -> 0.5775 | E19: =C19-D19 -> 0 | F19: =IF(C19=D19,"Tie",IF(C19>D19,"Tower A","Tower B")) -> Tie
A20: Sanitary | B20: Toilet Pipe Distribution & Hacking | C20: =AVERAGE(PROGRESSION!L6:L25) -> 0.4 | D20: =AVERAGE(PROGRESSION!L26:L45) -> 0.39 | E20: =C20-D20 -> 0.01 | F20: =IF(C20=D20,"Tie",IF(C20>D20,"Tower A","Tower B")) -> Tower A
A21: Sanitary | B21: Sanitary Toilets | C21: =AVERAGE(PROGRESSION!M6:M25) -> 0.665 | D21: =AVERAGE(PROGRESSION!M26:M45) -> 0.6425 | E21: =C21-D21 -> 0.0225 | F21: =IF(C21=D21,"Tie",IF(C21>D21,"Tower A","Tower B")) -> Tower A
A22: Sanitary | B22: Sanitary Wares Installation | C22: =AVERAGE(PROGRESSION!N6:N25) -> 0.1475 | D22: =AVERAGE(PROGRESSION!N26:N45) -> 0.1475 | E22: =C22-D22 -> 0 | F22: =IF(C22=D22,"Tie",IF(C22>D22,"Tower A","Tower B")) -> Tie
A23: Irrigation | B23: Irrigation Outlet | C23: =AVERAGE(PROGRESSION!O6:O25) -> 0.2 | D23: =AVERAGE(PROGRESSION!O26:O45) -> 0.2 | E23: =C23-D23 -> 0 | F23: =IF(C23=D23,"Tie",IF(C23>D23,"Tower A","Tower B")) -> Tie
A24: Irrigation | B24: Irrigation Inlet | C24: =AVERAGE(PROGRESSION!P6:P25) -> 0.045 | D24: =AVERAGE(PROGRESSION!P26:P45) -> 0.045 | E24: =C24-D24 -> 0 | F24: =IF(C24=D24,"Tie",IF(C24>D24,"Tower A","Tower B")) -> Tie
A25: Irrigation | B25: Irrigation Wiring | C25: =AVERAGE(PROGRESSION!Q6:Q25) -> 0 | D25: =AVERAGE(PROGRESSION!Q26:Q45) -> 0 | E25: =C25-D25 -> 0 | F25: =IF(C25=D25,"Tie",IF(C25>D25,"Tower A","Tower B")) -> Tie
A26: Irrigation | B26: Irrigation Control Panel | C26: =AVERAGE(PROGRESSION!R6:R25) -> 0 | D26: =AVERAGE(PROGRESSION!R26:R45) -> 0 | E26: =C26-D26 -> 0 | F26: =IF(C26=D26,"Tie",IF(C26>D26,"Tower A","Tower B")) -> Tie

Sheet ORDER
A1: Material Order | qty
A2: =PROGRESSION!A3&" · Blue = qty/floor and ordered" -> Report Date: 12 SEPTEMBER 2026 · Blue = qty/floor and ordered
A4: Package | B4: Material | C4: Unit | D4: Qty / floor | E4: Remaining A | F4: Remaining B | G4: Required | H4: Ordered | I4: Balance | J4: Status | K4: Remarks | M4: Package | N4: Required | O4: Ordered | P4: Balance
A5: Cold Water | B5: Pipe sleeve | C5: nos | D5: 1 | E5: {=SUM(IF(ISNUMBER(PROGRESSION!C6:C25),1-PROGRESSION!C6:C25,0))} -> 1.35 | F5: {=SUM(IF(ISNUMBER(PROGRESSION!C26:C45),1-PROGRESSION!C26:C45,0))} -> 1.4 | G5: =D5*(E5+F5) -> 2.75 | H5: 0 | I5: =G5-H5 -> 2.75 | J5: =IF(I5<=0,"Complete",IF(H5>0,"Partial","To Order")) -> To Order | M5: Cold Water | N5: =SUMIF($A$5:$A$23,M5,$G$5:$G$23) -> 72.9 | O5: =SUMIF($A$5:$A$23,M5,$H$5:$H$23) -> 0 | P5: =N5-O5 -> 72.9
A6: Cold Water | B6: Transfer pump pipes | C6: floor | D6: 1 | E6: {=SUM(IF(ISNUMBER(PROGRESSION!F6:F25),1-PROGRESSION!F6:F25,0))} -> 4.8 | F6: {=SUM(IF(ISNUMBER(PROGRESSION!F26:F45),1-PROGRESSION!F26:F45,0))} -> 13.35 | G6: =D6*(E6+F6) -> 18.15 | H6: 0 | I6: =G6-H6 -> 18.15 | J6: =IF(I6<=0,"Complete",IF(H6>0,"Partial","To Order")) -> To Order | M6: Sanitary | N6: =SUMIF($A$5:$A$23,M6,$G$5:$G$23) -> 405.7 | O6: =SUMIF($A$5:$A$23,M6,$H$5:$H$23) -> 0 | P6: =N6-O6 -> 405.7
A7: Cold Water | B7: CW tenant pipework | C7: floor | D7: 1 | E7: {=SUM(IF(ISNUMBER(PROGRESSION!H6:H25),1-PROGRESSION!H6:H25,0))} -> 3.85 | F7: {=SUM(IF(ISNUMBER(PROGRESSION!H26:H45),1-PROGRESSION!H26:H45,0))} -> 4.8 | G7: =D7*(E7+F7) -> 8.65 | H7: 0 | I7: =G7-H7 -> 8.65 | J7: =IF(I7<=0,"Complete",IF(H7>0,"Partial","To Order")) -> To Order | M7: Irrigation | N7: =SUMIF($A$5:$A$23,M7,$G$5:$G$23) -> 114.2 | O7: =SUMIF($A$5:$A$23,M7,$H$5:$H$23) -> 0 | P7: =N7-O7 -> 114.2
A8: Cold Water | B8: Backshaft CW & FW pipe | C8: floor | D8: 1 | E8: {=SUM(IF(ISNUMBER(PROGRESSION!I6:I25),1-PROGRESSION!I6:I25,0))} -> 17.15 | F8: {=SUM(IF(ISNUMBER(PROGRESSION!I26:I45),1-PROGRESSION!I26:I45,0))} -> 18 | G8: =D8*(E8+F8) -> 35.15 | H8: 0 | I8: =G8-H8 -> 35.15 | J8: =IF(I8<=0,"Complete",IF(H8>0,"Partial","To Order")) -> To Order | M8: TOTAL | N8: =SUM(N5:N7) -> 592.8 | O8: =SUM(O5:O7) -> 0 | P8: =SUM(P5:P7) -> 592.8
A9: Cold Water | B9: L31 & 31M roof piping | C9: lot | D9: 1 | E9: {=SUM(IF(ISNUMBER(PROGRESSION!G6:G25),1-PROGRESSION!G6:G25,0))} -> 2 | F9: {=SUM(IF(ISNUMBER(PROGRESSION!G26:G45),1-PROGRESSION!G26:G45,0))} -> 2 | G9: =D9*(E9+F9) -> 4 | H9: 0 | I9: =G9-H9 -> 4 | J9: =IF(I9<=0,"Complete",IF(H9>0,"Partial","To Order")) -> To Order
A10: Cold Water | B10: Pump | C10: set | D10: 1 | E10: {=SUM(IF(ISNUMBER(PROGRESSION!D6:D25),1-PROGRESSION!D6:D25,0))} -> 1.05 | F10: {=SUM(IF(ISNUMBER(PROGRESSION!D26:D45),1-PROGRESSION!D26:D45,0))} -> 1.05 | G10: =D10*(E10+F10) -> 2.1 | H10: 0 | I10: =G10-H10 -> 2.1 | J10: =IF(I10<=0,"Complete",IF(H10>0,"Partial","To Order")) -> To Order
A11: Cold Water | B11: Pump control panel | C11: set | D11: 1 | E11: {=SUM(IF(ISNUMBER(PROGRESSION!E6:E25),1-PROGRESSION!E6:E25,0))} -> 1.05 | F11: {=SUM(IF(ISNUMBER(PROGRESSION!E26:E45),1-PROGRESSION!E26:E45,0))} -> 1.05 | G11: =D11*(E11+F11) -> 2.1 | H11: 0 | I11: =G11-H11 -> 2.1 | J11: =IF(I11<=0,"Complete",IF(H11>0,"Partial","To Order")) -> To Order
A12: Sanitary | B12: Hosereel set | C12: nos | D12: 6 | E12: {=SUM(IF(ISNUMBER(PROGRESSION!J6:J25),1-PROGRESSION!J6:J25,0))} -> 8.45 | F12: {=SUM(IF(ISNUMBER(PROGRESSION!J26:J45),1-PROGRESSION!J26:J45,0))} -> 8.45 | G12: =D12*(E12+F12) -> 101.4 | H12: 0 | I12: =G12-H12 -> 101.4 | J12: =IF(I12<=0,"Complete",IF(H12>0,"Partial","To Order")) -> To Order
A13: Sanitary | B13: Floor trap | C13: nos | D13: 6 | E13: =E12 -> 8.45 | F13: =F12 -> 8.45 | G13: =D13*(E13+F13) -> 101.4 | H13: 0 | I13: =G13-H13 -> 101.4 | J13: =IF(I13<=0,"Complete",IF(H13>0,"Partial","To Order")) -> To Order
A14: Sanitary | B14: Sanitary stack pipe | C14: floor | D14: 1 | E14: =E12 -> 8.45 | F14: =F12 -> 8.45 | G14: =D14*(E14+F14) -> 16.9 | H14: 0 | I14: =G14-H14 -> 16.9 | J14: =IF(I14<=0,"Complete",IF(H14>0,"Partial","To Order")) -> To Order
A15: Sanitary | B15: Toilet distribution pipe | C15: floor | D15: 1 | E15: {=SUM(IF(ISNUMBER(PROGRESSION!L6:L25),1-PROGRESSION!L6:L25,0))} -> 12 | F15: {=SUM(IF(ISNUMBER(PROGRESSION!L26:L45),1-PROGRESSION!L26:L45,0))} -> 12.2 | G15: =D15*(E15+F15) -> 24.2 | H15: 0 | I15: =G15-H15 -> 24.2 | J15: =IF(I15<=0,"Complete",IF(H15>0,"Partial","To Order")) -> To Order
A16: Sanitary | B16: Sanitary tenant | C16: floor | D16: 1 | E16: {=SUM(IF(ISNUMBER(PROGRESSION!K6:K25),1-PROGRESSION!K6:K25,0))} -> 8.45 | F16: {=SUM(IF(ISNUMBER(PROGRESSION!K26:K45),1-PROGRESSION!K26:K45,0))} -> 8.45 | G16: =D16*(E16+F16) -> 16.9 | H16: 0 | I16: =G16-H16 -> 16.9 | J16: =IF(I16<=0,"Complete",IF(H16>0,"Partial","To Order")) -> To Order
A17: Sanitary | B17: WC pan | C17: nos | D17: 4 | E17: {=SUM(IF(ISNUMBER(PROGRESSION!M6:M25),1-PROGRESSION!M6:M25,0))} -> 6.7 | F17: {=SUM(IF(ISNUMBER(PROGRESSION!M26:M45),1-PROGRESSION!M26:M45,0))} -> 7.15 | G17: =D17*(E17+F17) -> 55.4 | H17: 0 | I17: =G17-H17 -> 55.4 | J17: =IF(I17<=0,"Complete",IF(H17>0,"Partial","To Order")) -> To Order
A18: Sanitary | B18: Wash basin | C18: nos | D18: 4 | E18: =E17 -> 6.7 | F18: =F17 -> 7.15 | G18: =D18*(E18+F18) -> 55.4 | H18: 0 | I18: =G18-H18 -> 55.4 | J18: =IF(I18<=0,"Complete",IF(H18>0,"Partial","To Order")) -> To Order
A19: Sanitary | B19: Sanitary wares | C19: floor | D19: 1 | E19: {=SUM(IF(ISNUMBER(PROGRESSION!N6:N25),1-PROGRESSION!N6:N25,0))} -> 17.05 | F19: {=SUM(IF(ISNUMBER(PROGRESSION!N26:N45),1-PROGRESSION!N26:N45,0))} -> 17.05 | G19: =D19*(E19+F19) -> 34.1 | H19: 0 | I19: =G19-H19 -> 34.1 | J19: =IF(I19<=0,"Complete",IF(H19>0,"Partial","To Order")) -> To Order
A20: Irrigation | B20: Irrigation outlet | C20: nos | D20: 1 | E20: {=SUM(IF(ISNUMBER(PROGRESSION!O6:O25),1-PROGRESSION!O6:O25,0))} -> 16 | F20: {=SUM(IF(ISNUMBER(PROGRESSION!O26:O45),1-PROGRESSION!O26:O45,0))} -> 16 | G20: =D20*(E20+F20) -> 32 | H20: 0 | I20: =G20-H20 -> 32 | J20: =IF(I20<=0,"Complete",IF(H20>0,"Partial","To Order")) -> To Order
A21: Irrigation | B21: Irrigation inlet | C21: nos | D21: 1 | E21: {=SUM(IF(ISNUMBER(PROGRESSION!P6:P25),1-PROGRESSION!P6:P25,0))} -> 19.1 | F21: {=SUM(IF(ISNUMBER(PROGRESSION!P26:P45),1-PROGRESSION!P26:P45,0))} -> 19.1 | G21: =D21*(E21+F21) -> 38.2 | H21: 0 | I21: =G21-H21 -> 38.2 | J21: =IF(I21<=0,"Complete",IF(H21>0,"Partial","To Order")) -> To Order
A22: Irrigation | B22: Irrigation cable | C22: floor | D22: 1 | E22: {=SUM(IF(ISNUMBER(PROGRESSION!Q6:Q25),1-PROGRESSION!Q6:Q25,0))} -> 20 | F22: {=SUM(IF(ISNUMBER(PROGRESSION!Q26:Q45),1-PROGRESSION!Q26:Q45,0))} -> 20 | G22: =D22*(E22+F22) -> 40 | H22: 0 | I22: =G22-H22 -> 40 | J22: =IF(I22<=0,"Complete",IF(H22>0,"Partial","To Order")) -> To Order
A23: Irrigation | B23: Irrigation control panel | C23: set | D23: 1 | E23: {=SUM(IF(ISNUMBER(PROGRESSION!R6:R25),1-PROGRESSION!R6:R25,0))} -> 2 | F23: {=SUM(IF(ISNUMBER(PROGRESSION!R26:R45),1-PROGRESSION!R26:R45,0))} -> 2 | G23: =D23*(E23+F23) -> 4 | H23: 0 | I23: =G23-H23 -> 4 | J23: =IF(I23<=0,"Complete",IF(H23>0,"Partial","To Order")) -> To Order
A24: TOTAL | E24: =SUM(E5:E23) -> 164.6 | F24: =SUM(F5:F23) -> 176.1 | G24: =SUM(G5:G23) -> 592.8 | H24: =SUM(H5:H23) -> 0 | I24: =SUM(I5:I23) -> 592.8

Sheet FLOORS
A1: Floor-by-floor | % complete
A2: ="A ahead "&COUNTIF(E5:E24,"Tower A")&" · B ahead "&COUNTIF(E5:E24,"Tower B")&" · tie "&COUNTIF(E5:E24,"Tie") -> A ahead 15 · B ahead 0 · tie 5
A4: Level | B4: Tower A | C4: Tower B | D4: Gap (A−B) | E4: Leader
A5: =PROGRESSION!A6 -> 13 | B5: =AVERAGE(PROGRESSION!C6:R6) -> 0.55833333 | C5: =AVERAGE(PROGRESSION!C26:R26) -> 0.55833333 | D5: =B5-C5 -> 0 | E5: =IF(B5=C5,"Tie",IF(B5>C5,"Tower A","Tower B")) -> Tie
A6: =PROGRESSION!A7 -> 14 | B6: =AVERAGE(PROGRESSION!C7:R7) -> 0.8 | C6: =AVERAGE(PROGRESSION!C27:R27) -> 0.8 | D6: =B6-C6 -> 0 | E6: =IF(B6=C6,"Tie",IF(B6>C6,"Tower A","Tower B")) -> Tie
A7: =PROGRESSION!A8 -> 15 | B7: =AVERAGE(PROGRESSION!C8:R8) -> 0.79583333 | C7: =AVERAGE(PROGRESSION!C28:R28) -> 0.79583333 | D7: =B7-C7 -> 0 | E7: =IF(B7=C7,"Tie",IF(B7>C7,"Tower A","Tower B")) -> Tie
A8: =PROGRESSION!A9 -> 16 | B8: =AVERAGE(PROGRESSION!C9:R9) -> 0.725 | C8: =AVERAGE(PROGRESSION!C29:R29) -> 0.65 | D8: =B8-C8 -> 0.075 | E8: =IF(B8=C8,"Tie",IF(B8>C8,"Tower A","Tower B")) -> Tower A
A9: =PROGRESSION!A10 -> 17 | B9: =AVERAGE(PROGRESSION!C10:R10) -> 0.49583333 | C9: =AVERAGE(PROGRESSION!C30:R30) -> 0.49166667 | D9: =B9-C9 -> 0.0041666667 | E9: =IF(B9=C9,"Tie",IF(B9>C9,"Tower A","Tower B")) -> Tower A
A10: =PROGRESSION!A11 -> 18 | B10: =AVERAGE(PROGRESSION!C11:R11) -> 0.49583333 | C10: =AVERAGE(PROGRESSION!C31:R31) -> 0.49166667 | D10: =B10-C10 -> 0.0041666667 | E10: =IF(B10=C10,"Tie",IF(B10>C10,"Tower A","Tower B")) -> Tower A
A11: =PROGRESSION!A12 -> 19 | B11: =AVERAGE(PROGRESSION!C12:R12) -> 0.4875 | C11: =AVERAGE(PROGRESSION!C32:R32) -> 0.48333333 | D11: =B11-C11 -> 0.0041666667 | E11: =IF(B11=C11,"Tie",IF(B11>C11,"Tower A","Tower B")) -> Tower A
A12: =PROGRESSION!A13 -> 20 | B12: =AVERAGE(PROGRESSION!C13:R13) -> 0.49583333 | C12: =AVERAGE(PROGRESSION!C33:R33) -> 0.41666667 | D12: =B12-C12 -> 0.079166667 | E12: =IF(B12=C12,"Tie",IF(B12>C12,"Tower A","Tower B")) -> Tower A
A13: =PROGRESSION!A14 -> 21 | B13: =AVERAGE(PROGRESSION!C14:R14) -> 0.47916667 | C13: =AVERAGE(PROGRESSION!C34:R34) -> 0.4 | D13: =B13-C13 -> 0.079166667 | E13: =IF(B13=C13,"Tie",IF(B13>C13,"Tower A","Tower B")) -> Tower A
A14: =PROGRESSION!A15 -> 22 | B14: =AVERAGE(PROGRESSION!C15:R15) -> 0.51538462 | C14: =AVERAGE(PROGRESSION!C35:R35) -> 0.44230769 | D14: =B14-C14 -> 0.073076923 | E14: =IF(B14=C14,"Tie",IF(B14>C14,"Tower A","Tower B")) -> Tower A
A15: =PROGRESSION!A16 -> 23 | B15: =AVERAGE(PROGRESSION!C16:R16) -> 0.40416667 | C15: =AVERAGE(PROGRESSION!C36:R36) -> 0.325 | D15: =B15-C15 -> 0.079166667 | E15: =IF(B15=C15,"Tie",IF(B15>C15,"Tower A","Tower B")) -> Tower A
A16: =PROGRESSION!A17 -> 24 | B16: =AVERAGE(PROGRESSION!C17:R17) -> 0.40416667 | C16: =AVERAGE(PROGRESSION!C37:R37) -> 0.2875 | D16: =B16-C16 -> 0.11666667 | E16: =IF(B16=C16,"Tie",IF(B16>C16,"Tower A","Tower B")) -> Tower A
... A24: =PROGRESSION!A25 -> 31M | B24: =AVERAGE(PROGRESSION!C25:R25) -> 0.00625 | C24: =AVERAGE(PROGRESSION!C45:R45) -> 0.00625 | D24: =B24-C24 -> 0 | E24: =IF(B24=C24,"Tie",IF(B24>C24,"Tower A","Tower B")) -> Tie
A25: OVERALL | B25: =AVERAGE(B5:B24) -> 0.44154006 | C25: =AVERAGE(C5:C24) -> 0.39584455 | D25: =B25-C25 -> 0.045695513 | E25: =IF(B25=C25,"Tie",IF(B25>C25,"Tower A","Tower B")) -> Tower A

Sheet SITE REPORT
A1: Site report | % complete
A2: =PROGRESSION!A3 -> Report Date: 12 SEPTEMBER 2026
A4: Overall | B4: Cold Water | C4: Sanitary | D4: Irrigation | E4: Men | F4: Day RM
A5: =(PROGRESSION!G4+PROGRESSION!L4+PROGRESSION!Q4)/3 -> 0.33585714 | B5: =PROGRESSION!G4 -> 0.47607143 | C5: =PROGRESSION!L4 -> 0.47025 | D5: =PROGRESSION!Q4 -> 0.06125 | E5: =COUNTA(Sheet2!C3:C29) -> 27 | F5: =Sheet2!D30 -> 15900
A7: Weather | B7: Fair | C7: Shift | D7: Day
A8: Today | B8: Transfer pump + hosereel
A9: Blockers
A10: Tomorrow
A12: Item | B12: Progress | C12: Status | D12: Owner
A13: =PROGRESSION!C$5 -> PIPE SLEEVE | B13: =PROGRESSION!C$46 -> 0.93125 | C13: =IF(B13>=0.9,"Complete",IF(B13>0,"In Progress","Not Started")) -> Complete
A14: =PROGRESSION!D$5 -> PUMP | B14: =PROGRESSION!D$46 -> 0.475 | C14: =IF(B14>=0.9,"Complete",IF(B14>0,"In Progress","Not Started")) -> In Progress
A15: =PROGRESSION!E$5 -> PUMP CONTROL PANEL | B15: =PROGRESSION!E$46 -> 0.475 | C15: =IF(B15>=0.9,"Complete",IF(B15>0,"In Progress","Not Started")) -> In Progress
A16: =PROGRESSION!F$5 -> TRANSFER PUMP PIPES | B16: =PROGRESSION!F$46 -> 0.54625 | C16: =IF(B16>=0.9,"Complete",IF(B16>0,"In Progress","Not Started")) -> In Progress
A17: =PROGRESSION!G$5 -> L31 & 31M ROOF PIPING | B17: =PROGRESSION!G$46 -> 0 | C17: =IF(B17>=0.9,"Complete",IF(B17>0,"In Progress","Not Started")) -> Not Started
A18: =PROGRESSION!H$5 -> CW TENANT | B18: =PROGRESSION!H$46 -> 0.78375 | C18: =IF(B18>=0.9,"Complete",IF(B18>0,"In Progress","Not Started")) -> In Progress
A19: =PROGRESSION!I$5 -> BACKSHAFT CW & FW TOILETS | B19: =PROGRESSION!I$46 -> 0.12125 | C19: =IF(B19>=0.9,"Complete",IF(B19>0,"In Progress","Not Started")) -> In Progress
A20: =PROGRESSION!J$5 -> HOSEREEL FLOORTRAP & STACK | B20: =PROGRESSION!J$46 -> 0.5775 | C20: =IF(B20>=0.9,"Complete",IF(B20>0,"In Progress","Not Started")) -> In Progress
A21: =PROGRESSION!K$5 -> SANITARY TENANT | B21: =PROGRESSION!K$46 -> 0.5775 | C21: =IF(B21>=0.9,"Complete",IF(B21>0,"In Progress","Not Started")) -> In Progress
A22: =PROGRESSION!L$5 -> TOILET PIPE DISTRIBUTION & HACKING | B22: =PROGRESSION!L$46 -> 0.395 | C22: =IF(B22>=0.9,"Complete",IF(B22>0,"In Progress","Not Started")) -> In Progress
A23: =PROGRESSION!M$5 -> SANITARY TOILETS | B23: =PROGRESSION!M$46 -> 0.65375 | C23: =IF(B23>=0.9,"Complete",IF(B23>0,"In Progress","Not Started")) -> In Progress
A24: =PROGRESSION!N$5 -> SANITARY WARES INSTALLATION | B24: =PROGRESSION!N$46 -> 0.1475 | C24: =IF(B24>=0.9,"Complete",IF(B24>0,"In Progress","Not Started")) -> In Progress
A25: =PROGRESSION!O$5 -> IRRIGATION OUTLET | B25: =PROGRESSION!O$46 -> 0.2 | C25: =IF(B25>=0.9,"Complete",IF(B25>0,"In Progress","Not Started")) -> In Progress
A26: =PROGRESSION!P$5 -> IRRIGATION INLET | B26: =PROGRESSION!P$46 -> 0.045 | C26: =IF(B26>=0.9,"Complete",IF(B26>0,"In Progress","Not Started")) -> In Progress
A27: =PROGRESSION!Q$5 -> IRRIGATION WIRING | B27: =PROGRESSION!Q$46 -> 0 | C27: =IF(B27>=0.9,"Complete",IF(B27>0,"In Progress","Not Started")) -> Not Started
A28: =PROGRESSION!R$5 -> IRRIGATION CONTROL PANEL | B28: =PROGRESSION!R$46 -> 0 | C28: =IF(B28>=0.9,"Complete",IF(B28>0,"In Progress","Not Started")) -> Not Started

Sheet PO LOG
A1: PO log | RM
A2: =PROGRESSION!A3 -> Report Date: 12 SEPTEMBER 2026
A4: Date | B4: PO No | C4: Material | D4: Supplier | E4: Qty | F4: Unit | G4: Amount RM | H4: Status | I4: ETA | J4: Remarks | L4: Still to order | M4: Lines
F5: =IF(C5="","",_xlfn.XLOOKUP(C5,ORDER!B$5:B$23,ORDER!C$5:C$23)) | L5: To Order | M5: =COUNTIF(ORDER!J5:J23,"To Order") -> 19
F6: =IF(C6="","",_xlfn.XLOOKUP(C6,ORDER!B$5:B$23,ORDER!C$5:C$23)) | L6: Partial | M6: =COUNTIF(ORDER!J5:J23,"Partial") -> 0
F7: =IF(C7="","",_xlfn.XLOOKUP(C7,ORDER!B$5:B$23,ORDER!C$5:C$23)) | L7: Complete | M7: =COUNTIF(ORDER!J5:J23,"Complete") -> 0
F8: =IF(C8="","",_xlfn.XLOOKUP(C8,ORDER!B$5:B$23,ORDER!C$5:C$23))
F9: =IF(C9="","",_xlfn.XLOOKUP(C9,ORDER!B$5:B$23,ORDER!C$5:C$23))
F10: =IF(C10="","",_xlfn.XLOOKUP(C10,ORDER!B$5:B$23,ORDER!C$5:C$23))
F11: =IF(C11="","",_xlfn.XLOOKUP(C11,ORDER!B$5:B$23,ORDER!C$5:C$23))
F12: =IF(C12="","",_xlfn.XLOOKUP(C12,ORDER!B$5:B$23,ORDER!C$5:C$23))
F13: =IF(C13="","",_xlfn.XLOOKUP(C13,ORDER!B$5:B$23,ORDER!C$5:C$23))
F14: =IF(C14="","",_xlfn.XLOOKUP(C14,ORDER!B$5:B$23,ORDER!C$5:C$23))
F15: =IF(C15="","",_xlfn.XLOOKUP(C15,ORDER!B$5:B$23,ORDER!C$5:C$23))
F16: =IF(C16="","",_xlfn.XLOOKUP(C16,ORDER!B$5:B$23,ORDER!C$5:C$23))
A17: TOTAL | E17: =SUM(E5:E16) -> 0 | G17: =SUM(G5:G16) -> 0 | H17: =COUNTA(H5:H16)&" POs" -> 0 POs

Sheet MANPOWER
A1: Manpower vs progress
A2: =PROGRESSION!A3 -> Report Date: 12 SEPTEMBER 2026
A4: On site | B4: Day RM | C4: Overall | D4: RM / 1% | F4: Package | G4: Progress | H4: Remaining
A5: =SUM(C8:C34) -> 27 | B5: =SUM(D8:D34) -> 15900 | C5: =('SITE REPORT'!A5) -> 0.33585714 | D5: =IF(C5=0,"",B5/(C5*100)) -> 473.41557 | F5: Cold Water | G5: =PROGRESSION!G4 -> 0.47607143 | H5: =1-G5 -> 0.52392857
F6: Sanitary | G6: =PROGRESSION!L4 -> 0.47025 | H6: =1-G6 -> 0.52975
A7: Name | B7: Rate RM | C7: On site | D7: Cost today | F7: Irrigation | G7: =PROGRESSION!Q4 -> 0.06125 | H7: =1-G7 -> 0.93875
A8: =Sheet2!C3 -> SUPAHAM | B8: =Sheet2!D3 -> 2000 | C8: 1 | D8: =IF(ISNUMBER(B8),B8*C8,0) -> 2000
A9: =Sheet2!C4 -> SOLIHIN | B9: =Sheet2!D4 -> 1000 | C9: 1 | D9: =IF(ISNUMBER(B9),B9*C9,0) -> 1000
A10: =Sheet2!C5 -> ASGAR | B10: =Sheet2!D5 -> 500 | C10: 1 | D10: =IF(ISNUMBER(B10),B10*C10,0) -> 500
A11: =Sheet2!C6 -> SUHAIRI | B11: =Sheet2!D6 -> 700 | C11: 1 | D11: =IF(ISNUMBER(B11),B11*C11,0) -> 700
A12: =Sheet2!C7 -> BILAL | B12: =Sheet2!D7 -> 500 | C12: 1 | D12: =IF(ISNUMBER(B12),B12*C12,0) -> 500
A13: =Sheet2!C8 -> JUWEL | B13: =Sheet2!D8 -> 500 | C13: 1 | D13: =IF(ISNUMBER(B13),B13*C13,0) -> 500
A14: =Sheet2!C9 -> JILLUR | B14: =Sheet2!D9 -> 500 | C14: 1 | D14: =IF(ISNUMBER(B14),B14*C14,0) -> 500
A15: =Sheet2!C10 -> SARIP | B15: =Sheet2!D10 -> 700 | C15: 1 | D15: =IF(ISNUMBER(B15),B15*C15,0) -> 700
A16: =Sheet2!C11 -> EMON | B16: =Sheet2!D11 -> 500 | C16: 1 | D16: =IF(ISNUMBER(B16),B16*C16,0) -> 500
A17: =Sheet2!C12 -> IBNU | B17: =Sheet2!D12 -> 500 | C17: 1 | D17: =IF(ISNUMBER(B17),B17*C17,0) -> 500
A18: =Sheet2!C13 -> KAMAL | B18: =Sheet2!D13 -> 500 | C18: 1 | D18: =IF(ISNUMBER(B18),B18*C18,0) -> 500
A19: =Sheet2!C14 -> YASIN | B19: =Sheet2!D14 -> 500 | C19: 1 | D19: =IF(ISNUMBER(B19),B19*C19,0) -> 500
... A34: =Sheet2!C29 -> KAMAL | B34: =Sheet2!D29 -> 500 | C34: 1 | D34: =IF(ISNUMBER(B34),B34*C34,0) -> 500
A35: TOTAL | C35: =SUM(C8:C34) -> 27 | D35: =SUM(D8:D34) -> 15900

Sheet ATTENDANCE
B1: 1 | C1: 2 | D1: 3 | E1: 4 | F1: 5 | G1: 6 | H1: 7 | I1: 8 | J1: 9 | K1: 10 | L1: 11 | M1: 12 | N1: 13 | O1: 14 | P1: 15 | Q1: 16 | R1: 17 | S1: 18 | T1: 19 | U1: 20 | V1: 21 | W1: 22 | X1: 23 | Y1: 24 | Z1: 25 | AA1: 26 | AB1: 27 | AC1: 28 | AD1: 29 | AE1: 30 | AF1: 31
A2: SUPAHAM
A3: SOLIHIN
A4: ASGAR
A5: SUHAIRI
A6: BILAL
A7: JUWEL
A8: JILLUR
A9: SARIP
A10: EMON
A11: IBNU
A12: KAMAL
A13: YASIN
... A28: KAMAL

Sheet aipoon
A1: Bill Of Quantities
A2: RE: | B2: UPVC PIPE FOR TOILET, TENANT AND HOSEREEL FOR LEVEL 24- LEVEL 31 @ MSK
A4: ITEM | B4: DESCRIPTION | C4: QUANTITY/UNIT | E4: UNIT RATE (RM) | F4: PREVIOUS CLAIM (%) | G4: WORK DONE (%) | H4: AMOUNT | I4: SIGN / VERIFY
A5: A | B5: SANITARY SERVICES
A7: 1 | B7: TOILET HIGH LEVEL AND DROPPER TOWER A & B (4SET OF TOILET) AT L25-L31
A8: 1.1 | B8: To install UPVC pipe waste and vent pipes and vertical stack including all fittings, cleaning eyes, brackets, bends, joints, flexible joints, vent cowl, traps, floor traps, floor outlet, brackets, hangers, off-sets, supports, etc
B9: LEVEL 25 | C9: Lot | D9: 1 | E9: ='[1]DETAILS REV1'!H11 -> 5800 | F9: 0 | G9: 0.95 | H9: =E9*G9 -> 5510
B10: LEVEL 26 | C10: Lot | D10: 1 | E10: ='[1]DETAILS REV1'!H12 -> 5800 | F10: 0 | G10: 0 | H10: =E10*G10 -> 0
B11: LEVEL 27 | C11: Lot | D11: 1 | E11: ='[1]DETAILS REV1'!H13 -> 5800 | F11: 0 | G11: 0.95 | H11: =E11*G11 -> 5510
B12: LEVEL 28 | C12: Lot | D12: 1 | E12: ='[1]DETAILS REV1'!H14 -> 5800 | F12: 0 | G12: 0 | H12: =E12*G12 -> 0
B13: LEVEL 29 | C13: Lot | D13: 1 | E13: ='[1]DETAILS REV1'!H15 -> 5800 | F13: 0 | G13: 0 | H13: =E13*G13 -> 0
B14: LEVEL 30 | C14: Lot | D14: 1 | E14: ='[1]DETAILS REV1'!H16 -> 5800 | F14: 0 | G14: 0 | H14: =E14*G14 -> 0
B15: LEVEL 31 | C15: Lot | D15: 1 | E15: ='[1]DETAILS REV1'!H17 -> 2900 | F15: 0 | G15: 0 | H15: =E15*G15 -> 0
A17: 2 | B17: TENANT OUTLET AND DROPPER TOWER A & B AT L25-L31
A18: 2.1 | B18: To install UPVC pipe waste and vent pipes and vertical stack including all fittings, cleaning eyes, brackets, bends, joints, flexible joints, vent cowl, traps, floor traps, floor outlet, brackets, hangers, off-sets, supports, etc
B19: LEVEL 25 | C19: Lot | D19: 1 | E19: ='[1]DETAILS REV1'!H22 -> 1600 | F19: 0 | G19: 0.95 | H19: =E19*G19 -> 1520
B20: LEVEL 26 | C20: Lot | D20: 1 | E20: ='[1]DETAILS REV1'!H23 -> 1600 | F20: 0 | G20: 0 | H20: =E20*G20 -> 0
B21: LEVEL 27 | C21: Lot | D21: 1 | E21: ='[1]DETAILS REV1'!H24 -> 1600 | F21: 0 | G21: 0.95 | H21: =E21*G21 -> 1520
B22: LEVEL 28 | C22: Lot | D22: 1 | E22: ='[1]DETAILS REV1'!H25 -> 1600 | F22: 0 | G22: 0 | H22: =E22*G22 -> 0
B23: LEVEL 29 | C23: Lot | D23: 1 | E23: ='[1]DETAILS REV1'!H26 -> 1600 | F23: 0 | G23: 0 | H23: =E23*G23 -> 0
B24: LEVEL 30 | C24: Lot | D24: 1 | E24: ='[1]DETAILS REV1'!H27 -> 1600 | F24: 0 | G24: 0 | H24: =E24*G24 -> 0
B25: LEVEL 31 | C25: Lot | D25: 1 | E25: ='[1]DETAILS REV1'!H28 -> 1600 | F25: 0 | G25: 0 | H25: =E25*G25 -> 0
A27: 3 | B27: HOSEREEL OUTLET AND DROPPER TOWER A & B AT L25-L31
A28: 3.1 | B28: To install UPVC pipe waste and vent pipes and vertical stack including all fittings, cleaning eyes, brackets, bends, joints, flexible joints, vent cowl, traps, floor traps, floor outlet, brackets, hangers, off-sets, supports, etc
B29: LEVEL 25 | C29: Lot | D29: 1 | E29: ='[1]DETAILS REV1'!H33 -> 510 | F29: 0 | G29: 0.95 | H29: =E29*G29 -> 484.5
B30: LEVEL 26 | C30: Lot | D30: 1 | E30: ='[1]DETAILS REV1'!H34 -> 510 | F30: 0 | G30: 0 | H30: =E30*G30 -> 0
B31: LEVEL 27 | C31: Lot | D31: 1 | E31: ='[1]DETAILS REV1'!H35 -> 510 | F31: 0 | G31: 0.95 | H31: =E31*G31 -> 484.5
B32: LEVEL 28 | C32: Lot | D32: 1 | E32: ='[1]DETAILS REV1'!H36 -> 510 | F32: 0 | G32: 0 | H32: =E32*G32 -> 0
B33: LEVEL 29 | C33: Lot | D33: 1 | E33: ='[1]DETAILS REV1'!H37 -> 510 | F33: 0 | G33: 0 | H33: =E33*G33 -> 0
B34: LEVEL 30 | C34: Lot | D34: 1 | E34: ='[1]DETAILS REV1'!H38 -> 510 | F34: 0 | G34: 0 | H34: =E34*G34 -> 0
B35: LEVEL 31 | C35: Lot | D35: 1 | E35: ='[1]DETAILS REV1'!H39 -> 510 | F35: 0 | G35: 0 | H35: =E35*G35 -> 0
A37: 4 | B37: ADDITIONAL
B38: TOILET HIGH LEVEL AND DROPPER TOWER A&B (2SET OF TOILET) AT L24
B39: LEVEL 24 TOWER B | C39: Lot | D39: 1 | E39: ='[1]DETAILS REV1'!H45 -> 2900 | F39: 0 | G39: 0 | H39: =E39*G39 -> 0
B40: LEVEL 24 TOWER A (BRICKWALL) | C40: Lot | D40: 1 | E40: ='[1]DETAILS REV1'!H46 -> 2900 | F40: 0 | G40: 0 | H40: =E40*G40 -> 0
B53: TOTAL AMOUNT | E53: =SUM(E9:E15,E19:E25,E29:E35,E39:E40) -> 58270 | H53: =SUM(H9:H15,H19:H25,H29:H35,H39:H40) -> 15029
A55: VERIFICATION
A56: Prepared by | D56: Checked by | G56: Verified / Approved
A57: Sign: | D57: Sign: | G57: Sign:
A58: Name: ALVIN | D58: Name: KHAIRUL | G58: Name: AH FATT
...

Sheet ariyan
A1: Bill Of Quantities
A2: RE: | B2: STAINLESS STEEL TRANSFER PUMP PIPE | TOWER A AND TOWER B @ MSK
A3: RATE: RM 80 PER METER, ADDITIONAL FITTINGS RM 150 PER NO. (ELBOW / CHECK VALVE), RM 80 PER SAMPLING POINT
A4: ITEM | B4: DESCRIPTION | C4: QUANTITY/UNIT | E4: UNIT RATE (RM) | F4: PREVIOUS CLAIM (%) | G4: WORK DONE (%) | H4: AMOUNT | I4: SIGN / VERIFY
A5: A | B5: WORKER LABOUR
A6: 1.0 | B6: TOWER A | STAINLESS STEEL TRANSFER PUMP PIPE
A7: 1.1 | B7: To install stainless steel transfer pump pipe
B8: LEVEL 13 | C8: m | D8: 10.75 | E8: 80 | F8: 0 | G8: 0.95 | H8: =D8*E8*G8 -> 817
B9: LEVEL 14 | C9: m | D9: 4.5 | E9: 80 | F9: 0 | G9: 0.95 | H9: =D9*E9*G9 -> 342
B10: LEVEL 15 | C10: m | D10: 4.5 | E10: 80 | F10: 0 | G10: 0.95 | H10: =D10*E10*G10 -> 342
B11: LEVEL 16 | C11: m | D11: 4.5 | E11: 80 | F11: 0 | G11: 0.95 | H11: =D11*E11*G11 -> 342
B12: LEVEL 17 | C12: m | D12: 4.5 | E12: 80 | F12: 0 | G12: 0.95 | H12: =D12*E12*G12 -> 342
B13: LEVEL 18 | C13: m | D13: 4.5 | E13: 80 | F13: 0 | G13: 0.95 | H13: =D13*E13*G13 -> 342
B14: LEVEL 19 | C14: m | D14: 4.5 | E14: 80 | F14: 0 | G14: 0.95 | H14: =D14*E14*G14 -> 342
B15: LEVEL 20 | C15: m | D15: 4.5 | E15: 80 | F15: 0 | G15: 0.95 | H15: =D15*E15*G15 -> 342
B16: LEVEL 21 | C16: m | D16: 4.5 | E16: 80 | F16: 0 | G16: 0.95 | H16: =D16*E16*G16 -> 342
B17: LEVEL 22 | C17: m | D17: 4.5 | E17: 80 | F17: 0 | G17: 0 | H17: =D17*E17*G17 -> 0
B18: LEVEL 23 | C18: m | D18: 4.5 | E18: 80 | F18: 0 | G18: 0 | H18: =D18*E18*G18 -> 0
B19: LEVEL 24 | C19: m | D19: 4.5 | E19: 80 | F19: 0 | G19: 0 | H19: =D19*E19*G19 -> 0
... B26: LEVEL 31 | C26: m | D26: 12.7 | E26: 80 | F26: 0 | G26: 0 | H26: =D26*E26*G26 -> 0
A28: 1.2 | B28: Additional fittings. Rate RM150 per no. (elbow / check valve).
B29: LEVEL 13 | ELBOW | C29: NOS | D29: 3 | E29: 150 | F29: 0 | G29: 0.95 | H29: =D29*E29*G29 -> 427.5
B30: LEVEL 14 | ELBOW / CHECK VALVE | C30: NOS | D30: 2 | E30: 150 | F30: 0 | G30: 0.95 | H30: =D30*E30*G30 -> 285
B31: LEVEL 21 | ELBOW | C31: NOS | D31: 2 | E31: 150 | F31: 0 | G31: 0 | H31: =D31*E31*G31 -> 0
B32: LEVEL 23 | CHECK VALVE | C32: NOS | D32: 1 | E32: 150 | F32: 0 | G32: 0 | H32: =D32*E32*G32 -> 0
B33: LEVEL 13 | SAMPLING POINT | C33: NOS | D33: 1 | E33: 80 | F33: 0 | G33: 1 | H33: =D33*E33*G33 -> 80
B34: LEVEL 23 | SAMPLING POINT | C34: NOS | D34: 1 | E34: 80 | F34: 0 | G34: 0 | H34: =D34*E34*G34 -> 0
A36: 2.0 | B36: TOWER B | STAINLESS STEEL TRANSFER PUMP PIPE
A37: 2.1 | B37: To install stainless steel transfer pump pipe
B38: LEVEL 21 | C38: m | D38: 4.5 | E38: 80 | F38: 0 | G38: 0.95 | H38: =D38*E38*G38 -> 342
B39: LEVEL 22 | C39: m | D39: 4.5 | E39: 80 | F39: 0 | G39: 0.95 | H39: =D39*E39*G39 -> 342
B40: LEVEL 23 | C40: m | D40: 4.5 | E40: 80 | F40: 0 | G40: 0.95 | H40: =D40*E40*G40 -> 342
B41: LEVEL 24 | C41: m | D41: 4.5 | E41: 80 | F41: 0 | G41: 0.95 | H41: =D41*E41*G41 -> 342
B42: LEVEL 25 | C42: m | D42: 4.5 | E42: 80 | F42: 0 | G42: 0.95 | H42: =D42*E42*G42 -> 342
B43: LEVEL 26 | C43: m | D43: 4.5 | E43: 80 | F43: 0 | G43: 0.95 | H43: =D43*E43*G43 -> 342
B44: LEVEL 27 | C44: m | D44: 5.1 | E44: 80 | F44: 0 | G44: 0.95 | H44: =D44*E44*G44 -> 387.6
B45: LEVEL 28 | C45: m | D45: 5.1 | E45: 80 | F45: 0 | G45: 0.95 | H45: =D45*E45*G45 -> 387.6
B46: LEVEL 29 | C46: m | D46: 5.1 | E46: 80 | F46: 0 | G46: 0.95 | H46: =D46*E46*G46 -> 387.6
B47: LEVEL 30 | C47: m | D47: 6 | E47: 80 | F47: 0 | G47: 0 | H47: =D47*E47*G47 -> 0
B48: LEVEL 31 | C48: m | D48: 12.7 | E48: 80 | F48: 0 | G48: 0 | H48: =D48*E48*G48 -> 0
...

Sheet Sheet2
B2: GM | E2: SUBS
B3: 1 | C3: SUPAHAM | D3: 2000 | E3: 1 | F3: AIPOON | G3: 0
B4: 2 | C4: SOLIHIN | D4: 1000 | E4: 2 | F4: WELDER
B5: 3 | C5: ASGAR | D5: 500
B6: 4 | C6: SUHAIRI | D6: 700
B7: 5 | C7: BILAL | D7: 500
B8: 6 | C8: JUWEL | D8: 500
B9: 7 | C9: JILLUR | D9: 500
B10: 8 | C10: SARIP | D10: 700
B11: 9 | C11: EMON | D11: 500
B12: 10 | C12: IBNU | D12: 500
B13: 11 | C13: KAMAL | D13: 500
B14: 12 | C14: YASIN | D14: 500
B15: 13 | C15: SOFIKUL | D15: 1000
B16: 14 | C16: NAZMUL | D16: 500
... B18: 16 | C18: NURUL | D18: 500
B19: 17 | C19: JIARUL | D19: n/a
B20: 18 | C20: SUPENDI | D20: 500
B21: 19 | C21: RANA | D21: 500
B22: 20 | C22: ASHRAFUL | D22: 500
B23: 21 | C23: FARHAD | D23: 500
B24: 22 | C24: BADOL | D24: 500
B25: 23 | C25: ISLAM | D25: 500
B26: 24 | C26: SYAHIB | D26: 500
B27: 25 | C27: AMIRUL | D27: 500
B28: 26 | C28: DAMIL | D28: 500
B29: 27 | C29: KAMAL | D29: 500
C30: TOTAL | D30: =SUM(D3:D29) -> 15900
